Failure # 1 (occurred at 2020-08-11_13-18-09)
Traceback (most recent call last):
  File "/usr/local/lib/python3.6/dist-packages/ray/tune/trial_runner.py", line 468, in _process_trial
    result = self.trial_executor.fetch_result(trial)
  File "/usr/local/lib/python3.6/dist-packages/ray/tune/ray_trial_executor.py", line 430, in fetch_result
    result = ray.get(trial_future[0], DEFAULT_GET_TIMEOUT)
  File "/usr/local/lib/python3.6/dist-packages/ray/worker.py", line 1474, in get
    raise value.as_instanceof_cause()
ray.exceptions.RayTaskError(ValueError): [36mray::DDPPO.train()[39m (pid=2078, ip=172.17.0.3)
  File "python/ray/_raylet.pyx", line 407, in ray._raylet.execute_task
  File "python/ray/_raylet.pyx", line 442, in ray._raylet.execute_task
  File "python/ray/_raylet.pyx", line 445, in ray._raylet.execute_task
  File "python/ray/_raylet.pyx", line 446, in ray._raylet.execute_task
  File "python/ray/_raylet.pyx", line 400, in ray._raylet.execute_task.function_executor
  File "/usr/local/lib/python3.6/dist-packages/ray/rllib/agents/trainer_template.py", line 90, in __init__
    Trainer.__init__(self, config, env, logger_creator)
  File "/usr/local/lib/python3.6/dist-packages/ray/rllib/agents/trainer.py", line 450, in __init__
    super().__init__(config, logger_creator)
  File "/usr/local/lib/python3.6/dist-packages/ray/tune/trainable.py", line 175, in __init__
    self._setup(copy.deepcopy(self.config))
  File "/usr/local/lib/python3.6/dist-packages/ray/rllib/agents/trainer.py", line 623, in _setup
    self._init(self.config, self.env_creator)
  File "/usr/local/lib/python3.6/dist-packages/ray/rllib/agents/trainer_template.py", line 94, in _init
    validate_config(config)
  File "/usr/local/lib/python3.6/dist-packages/ray/rllib/agents/ppo/ddppo.py", line 75, in validate_config
    "Distributed data parallel is only supported for PyTorch")
ValueError: Distributed data parallel is only supported for PyTorch

