Failure # 1 (occurred at 2020-08-11_13-23-28)
Traceback (most recent call last):
  File "/usr/local/lib/python3.6/dist-packages/ray/tune/trial_runner.py", line 468, in _process_trial
    result = self.trial_executor.fetch_result(trial)
  File "/usr/local/lib/python3.6/dist-packages/ray/tune/ray_trial_executor.py", line 430, in fetch_result
    result = ray.get(trial_future[0], DEFAULT_GET_TIMEOUT)
  File "/usr/local/lib/python3.6/dist-packages/ray/worker.py", line 1474, in get
    raise value.as_instanceof_cause()
ray.exceptions.RayTaskError(AssertionError): [36mray::IMPALA.train()[39m (pid=13161, ip=172.17.0.3)
  File "python/ray/_raylet.pyx", line 407, in ray._raylet.execute_task
  File "python/ray/_raylet.pyx", line 442, in ray._raylet.execute_task
  File "python/ray/_raylet.pyx", line 445, in ray._raylet.execute_task
  File "python/ray/_raylet.pyx", line 446, in ray._raylet.execute_task
  File "python/ray/_raylet.pyx", line 400, in ray._raylet.execute_task.function_executor
  File "/usr/local/lib/python3.6/dist-packages/ray/rllib/agents/trainer_template.py", line 90, in __init__
    Trainer.__init__(self, config, env, logger_creator)
  File "/usr/local/lib/python3.6/dist-packages/ray/rllib/agents/trainer.py", line 450, in __init__
    super().__init__(config, logger_creator)
  File "/usr/local/lib/python3.6/dist-packages/ray/tune/trainable.py", line 175, in __init__
    self._setup(copy.deepcopy(self.config))
  File "/usr/local/lib/python3.6/dist-packages/ray/rllib/agents/trainer.py", line 623, in _setup
    self._init(self.config, self.env_creator)
  File "/usr/local/lib/python3.6/dist-packages/ray/rllib/agents/trainer_template.py", line 125, in _init
    self.train_exec_impl = execution_plan(self.workers, config)
  File "/usr/local/lib/python3.6/dist-packages/ray/rllib/agents/impala/impala.py", line 234, in execution_plan
    learner_thread = make_learner_thread(workers.local_worker(), config)
  File "/usr/local/lib/python3.6/dist-packages/ray/rllib/agents/impala/impala.py", line 138, in make_learner_thread
    learner_queue_timeout=config["learner_queue_timeout"])
  File "/usr/local/lib/python3.6/dist-packages/ray/rllib/execution/multi_gpu_learner.py", line 74, in __init__
    assert self.train_batch_size % len(self.devices) == 0
AssertionError

